Workbook

Sheet INSTRUCTIONS
A2: Background: | B2: In preparation for the migration of IIS data to the new Regulatory Oversight Management System, it is important to identify groupings of companies based on the parent regulated entity.
A3: Purpose: | B3: Identify all companies that should be grouped together under a single/common parent company/regulated entity.
A4: Instructions: | B4: 1. Sort the COMPANY_NAME(formatted) column (D) from lowest to highest.
B5: 2. Apply the following filters: a) ASSIGNED TO (column B) to show your name only b) COMPLETED (column A) to show "N" only
B6: 3. Scroll over to Column E (Planned2021) and identify the first "Y" record. This indicates that the site was planned for inspection in 2020/2021. All planned sites should be addressed first; however do not filter this column because this may conceal other companies that should be grouoped with it and may have the same name.
B7: 4. Keeping #3 in mind, look through the values of COMPANY_NAME (formatted) and regulated entity name to identify groups of records that can be united under one legal name, (e.g. ‘NEWALTA’ and ‘NEWALTA CORPORATION’, or ‘CN RAIL’ and ‘CANADIAN NATIONAL RAILWAY’).
B8: 5. Use COMPANY_NAME (formatted) or regulated entity name to search for the company's legal name in the provincial and federal registries (the list of registry websites is available below). If the company name is not found in the provided registries, use Google to search by the company name (colummn D) as well as the site address (columns G - I) . Usually a legal name can be found at the bottom of a company website.
B9: 6. Based on the information discovered through the previous step, create a grouping of regulated entities by entering the official company name for all applicable records in the Consolidated...Name fields (Q - S).
B10: 7. Ensure that the selected group of records has the same regulated entity id (column O). Update this field if necessary, e.g: - IF the regulated entity id for 'CN RAIL' is 123; - AND the regulated entity id for ‘CANADIAN NATIONAL RAILWAY’ is 456; - AND your search reveals that the Consolidated Official Name for both records should be 'CANADIAN NATIONAL RAILWAY'; - THEN change the regulated entity id for 'CN RAIL' from 123 to 456 and enter 'CANADIAN NATIONAL RAILWAY' in column Q & R for both records.
A12: LIST OF BUSINESS REGISTRIES*
A13: Province/Territory | B13: URL | C13: Username | D13: Password
A14: (National) Canadian Companies Database | B14: https://www.canada.ca/en/services/business/research/directoriescanadiancompanies.html | C14: Free -Not required | D14: Free -Not required
A15: Newfoundland | B15: https://cado.eservices.gov.nl.ca/CADOInternet/Company/CompanyNameNumberSearch.aspx | C15: Free -Not required | D15: Free -Not required
A16: Prince Edward Island | B16: http://www.gov.pe.ca/corporations/index.php | C16: Free -Not required | D16: Free -Not required
A17: Nova Scotia | B17: https://rjsc.gov.ns.ca/rjsc/search/inquiry.do | C17: Free -Not required | D17: Free -Not required
A18: New Brunswick | B18: https://www.pxw2.snb.ca/card_online/Search/search.aspx | C18: TBD | D18: TBD
A19: Quebec | B19: http://www.registreentreprises.gouv.qc.ca/en/ | C19: Free -Not required | D19: Free -Not required
A20: Ontario | B20: http://www.carswelllegalsolutions.com/corporation-and-business-name-information/ | C20: TBD | D20: TBD
A21: Manitoba | B21: http://www.companiesoffice.gov.mb.ca/search_registry.html | C21: Free -Not required | D21: Free -Not required
A22: Saskatchewan | B22: https://corporateregistry.isc.ca/ | C22: DQWG | D22: Dqwg2017
A23: British Columbia | B23: https://www2.gov.bc.ca/gov/content/governments/organizational-structure/ministries-organizations/ministries/citizens-services/bc-registries-online-services | C23: TBD | D23: TBD
A24: Yukon Territory | B24: https://ycor-reey.gov.yk.ca/search | C24: Free -Not required | D24: Free -Not required
... A26: Nunavut | B26: http://nunavutlegalregistries.ca/cr_index_en.shtml | C26: TBD | D26: TBD
A27: *These sources are out-dated and some links may malfunction. If this occurs, the most reliable source is the national, Canadian Companies Database.

Sheet MATCHRESULTS
A1: COMPLETED | B1: ASSIGNED TO | C1: IIS_ID | D1: COMPANY_NAME (formatted) | E1: Planned2021 | F1: COMPANY_NAME | G1: COUNTRY_SUBDIVISION_CD | H1: CITY_TOWN_NAME_NM | I1: Address | J1: POSTAL_CODE_TXT | K1: FILE_STATUS_CD | L1: SOUNDEX (Name) | M1: Matching ID | N1: Fuzzy Match | O1: regulated entity id | P1: regulated entity name | Q1: Consolidated Common English Name | R1: Consolidated Common French Name | S1: Notes | T1: For Discussion
A2: =IF(OR(Q2<>"",R2<>""),"Y","N") -> Y | B2: WILFREDA EDWARD-DOLCY | C2: 23289 | D2: E FOCUS TECHNOLOGY CORP | E2: Y | F2: E-FOCUS TECHNOLOGY CORP. | G2: BC | H2: VANCOUVER | I2: 510 EAST KENT AVENUE SOUTH | J2: V5X4V6 | K2: ACTIVE | L2: E122 | M2: 23289 | N2: E FOCUS TECHNOLOGY CORP | O2: 23289E122 | P2: E FOCUS TECHNOLOGY CORP | Q2: E-FOCUS TECHNOLOGY CORP
A3: =IF(OR(Q3<>"",R3<>""),"Y","N") -> Y | B3: WILFREDA EDWARD-DOLCY | C3: 20284 | D3: E ONE MOLI ENERGY CANADA LTD | E3: N | F3: E-ONE MOLI ENERGY (CANADA) LTD | G3: BC | H3: MAPLE RIDGE | I3: 20000 STEWART CRES. | J3: V2X 9E7 | K3: ACTIVE | L3: E554 | M3: 20284 | N3: E ONE MOLI ENERGY CANADA LTD | O3: 20284E554 | P3: E ONE MOLI ENERGY CANADA LTD | Q3: E-ONE MOLI ENERGY (CANADA) LIMITED
A4: =IF(OR(Q4<>"",R4<>""),"Y","N") -> Y | B4: WILFREDA EDWARD-DOLCY | C4: 3052741 | D4: EGGR TRANSPORT | E4: N | F4: EGGR Transport | G4: QC | H4: L'ASSOMPTION | I4: 45 ARBOIT | J4: J5W4P3 | K4: ACTIVE | L4: E263 | M4: 3052741 | N4: EGGR TRANSPORT | O4: 3052741E263 | P4: EGGR TRANSPORT | R4: LES ENTREPRISES DE GESTION GEORGES & ROBERT INC.
A5: =IF(OR(Q5<>"",R5<>""),"Y","N") -> Y | B5: WILFREDA EDWARD-DOLCY | C5: 1795076 | D5: EHMAN VENTURES LTD | E5: N | F5: EHMAN VENTURES LTD. | G5: MB | H5: CORMORANT | I5: 0 GD | J5: R0B0G0 | K5: ACTIVE | L5: E551 | M5: 1795076 | N5: EHMAN VENTURES LTD | O5: 1795076E551 | P5: EHMAN VENTURES LTD | Q5: EHMAN VENTURES LTD.
A6: =IF(OR(Q6<>"",R6<>""),"Y","N") -> Y | B6: WILFREDA EDWARD-DOLCY | C6: 23024 | D6: EIDAM DIAGNOSTICS CORPORATION DERMAMED | E6: N | F6: EIDAM DIAGNOSTICS CORPORATION / DERMAMED | G6: BC | H6: RICHMOND | I6: 11120 HORSESHOE WAY UNIT 140 | J6: V7A5H7 | K6: ACTIVE | L6: E353 | M6: 23024 | N6: EIDAM DIAGNOSTICS CORPORATION DERMAMED | O6: 23024E353 | P6: EIDAM DIAGNOSTICS CORPORATION DERMAMED | Q6: DERMAMED PHARMACEUTICAL INC.
A7: =IF(OR(Q7<>"",R7<>""),"Y","N") -> Y | B7: WILFREDA EDWARD-DOLCY | C7: 6091 | D7: EIFCO INC | E7: Y | F7: EIFCO INC | G7: QC | H7: SAINT-LAURENT | I7: 9430 HENRI-BOURASSA | J7: H4S1N8 | K7: ACTIVE | L7: E125 | M7: 6091 | N7: EIFCO INC | O7: 6091E125 | P7: EIFCO INC | Q7: Electrowind Supply Inc
A8: =IF(OR(Q8<>"",R8<>""),"Y","N") -> Y | B8: WILFREDA EDWARD-DOLCY | C8: 1793841 | D8: EILERS TRUCKING INC | E8: N | F8: EILERS TRUCKING INC. | G8: SK | H8: REDVERS | I8: 828 PO | J8: S0C2H0 | K8: ACTIVE | L8: E462 | M8: 1793841 | N8: EILERS TRUCKING INC | O8: 1793841E462 | P8: EILERS TRUCKING INC | Q8: EILERS TRUCKING INC.
A9: =IF(OR(Q9<>"",R9<>""),"Y","N") -> Y | B9: WILFREDA EDWARD-DOLCY | C9: 4273 | D9: EKA CHIMIE CANADA INC | E9: Y | F9: EKA CHIMIE CANADA INC | G9: QC | H9: MAGOG | I9: 1900, RUE ST-PATRICE EST | J9: J1X 4X6 | K9: ACTIVE | L9: E225 | M9: 2613 | N9: EKA CHIMIE CANADA INC | O9: 2613E225 | P9: EKA CHIMIE CANADA INC | Q9: NOURYON CHEMICALS LTD.
A10: =IF(OR(Q10<>"",R10<>""),"Y","N") -> Y | B10: WILFREDA EDWARD-DOLCY | C10: 2613 | D10: EKA CHIMIE CANADA INC | E10: N | F10: EKA CHIMIE CANADA INC. | G10: QC | H10: SALABERRY-DE-VALLEYFIELD | I10: 640, RUE DES ERABLES | J10: J6T 6G4 | K10: ACTIVE | L10: E225 | M10: 2613 | N10: EKA CHIMIE CANADA INC | O10: 2613E225 | P10: EKA CHIMIE CANADA INC | Q10: NOURYON CHEMICALS LTD.
A11: =IF(OR(Q11<>"",R11<>""),"Y","N") -> Y | B11: WILFREDA EDWARD-DOLCY | C11: 12285 | D11: ELANCO ANIMAL HEALTH | E11: N | F11: ELANCO ANIMAL HEALTH | G11: ON | H11: GUELPH | I11: 150 RESEARCH LANE SUITE 120 | J11: N1G 4T2 | K11: ACTIVE | L11: E452 | M11: 12285 | N11: ELANCO ANIMAL HEALTH | O11: 12332E444 | P11: ELANCO ANIMAL HEALTH | Q11: ELI LILLY CANADA INC.
A12: =IF(OR(Q12<>"",R12<>""),"Y","N") -> Y | B12: WILFREDA EDWARD-DOLCY | C12: 12421 | D12: ELCAN OPTICAL TECHNOLOGIES | E12: N | F12: ELCAN OPTICAL TECHNOLOGIES | G12: ON | H12: MIDLAND | I12: 450 LEITZ ROAD (OFF ELLEN ROAD) | J12: L4R 5B8 | K12: ACTIVE | L12: E425 | M12: 12421 | N12: ELCAN OPTICAL TECHNOLOGIES | O12: 12421E425 | P12: ELCAN OPTICAL TECHNOLOGIES | Q12: Raytheon Canada Limited | R12: Raytheon Canada Limitée
A13: =IF(OR(Q13<>"",R13<>""),"Y","N") -> Y | B13: WILFREDA EDWARD-DOLCY | C13: 1034057 | D13: ELCANO EXPLORATION | E13: N | F13: Elcano Exploration | G13: AB | H13: CALGARY | I13: 550 6 | J13: T2P0S2 | K13: ACTIVE | L13: E425 | M13: 1034057 | N13: ELCANO EXPLORATION | O13: 1034057E425 | P13: ELCANO EXPLORATION | Q13: ELCANO EXPLORATION LTD.
A14: =IF(OR(Q14<>"",R14<>""),"Y","N") -> Y | B14: WILFREDA EDWARD-DOLCY | C14: 3905 | D14: ELCO LTD | E14: N | F14: ELCO LTD | G14: NS | H14: HALIFAX | I14: 61 RADDALL AVE BURNSIDE INDUSTRIAL PARK | J14: B3B 1T4 | K14: ACTIVE | L14: E424 | M14: 3905 | N14: ELCO LTD | O14: 3905E424 | P14: ELCO LTD | Q14: ELCO LTD.
A15: =IF(OR(Q15<>"",R15<>""),"Y","N") -> Y | B15: WILFREDA EDWARD-DOLCY | C15: 852 | D15: ELCO LTD | E15: N | F15: ELCO LTD. | G15: NB | H15: BATHURST | I15: 1805 VANIER BLVD. | J15: E2A 7B7 | K15: ACTIVE | L15: E424 | M15: 3905 | N15: ELCO LTD | O15: 3905E424 | P15: ELCO LTD | Q15: ELCO LTD.
A16: =IF(OR(Q16<>"",R16<>""),"Y","N") -> Y | B16: WILFREDA EDWARD-DOLCY | C16: 7633563 | D16: ELECTRIC BIKE BREWING COMPANY | E16: N | F16: Electric Bike Brewing Company | G16: BC | H16: VANCOUVER | I16: 20 4TH | J16: V5T1E8 | K16: ACTIVE | L16: E423 | M16: 7633563 | N16: ELECTRIC BIKE BREWING COMPANY | O16: 7633563E423 | P16: ELECTRIC BIKE BREWING COMPANY | Q16: ELECTRIC BICYCLE BREWING INC.
A17: =IF(OR(Q17<>"",R17<>""),"Y","N") -> Y | B17: WILFREDA EDWARD-DOLCY | C17: 20777 | D17: ELECTRIC INSULATION MATERIALS LTD | E17: N | F17: ELECTRIC INSULATION MATERIALS LTD. | G17: BC | H17: COQUITLAM | I17: 2423 CANOE STREET | J17: V3K 6A9 | K17: ACTIVE | L17: E423 | M17: 20777 | N17: ELECTRIC INSULATION MATERIALS LTD | O17: 20777E423 | P17: ELECTRIC INSULATION MATERIALS LTD | Q17: EIM Electric Insulation Materials (Vanc.) Ltd. | S17: not found in DB
A18: =IF(OR(Q18<>"",R18<>""),"Y","N") -> Y | B18: WILFREDA EDWARD-DOLCY | C18: 4112705 | D18: ELECTRIC MOTORCYCLES WINDSOR | E18: Y | F18: Electric Motorcycles Windsor | G18: ON | H18: WINDSOR | I18: 3143 WALKER | J18: N8W3R6 | K18: ACTIVE | L18: E423 | M18: 4112705 | N18: ELECTRIC MOTORCYCLES WINDSOR | O18: 4112705E423 | P18: ELECTRIC MOTORCYCLES WINDSOR | Q18: SOAR Hobby & more
A19: =IF(OR(Q19<>"",R19<>""),"Y","N") -> Y | B19: WILFREDA EDWARD-DOLCY | C19: 833 | D19: ELECTRICAL AND REFRIGERATION SRV LTD | E19: Y | F19: ELECTRICAL & REFRIGERATION SRV. LTD. | G19: NB | H19: MONCTON | I19: 88 BEAVERBROOK STREET P O BOX 2010, STATION A | J19: E1C 8N8 | K19: ACTIVE | L19: E423 | M19: 833 | N19: ELECTRICAL AND REFRIGERATION SRV LTD | O19: 833E423 | P19: ELECTRICAL AND REFRIGERATION SRV LTD | Q19: Charmichael Engineering
A20: =IF(OR(Q20<>"",R20<>""),"Y","N") -> Y | B20: WILFREDA EDWARD-DOLCY | C20: 12288 | D20: ELECTRICAL CONTACTS LIMITED | E20: Y | F20: ELECTRICAL CONTACTS LIMITED. | G20: ON | H20: HANOVER | I20: 519-22ND. AVE. | J20: N4N 3C4 | K20: ACTIVE | L20: E423 | M20: 12288 | N20: ELECTRICAL CONTACTS LIMITED | O20: 12288E423 | P20: ELECTRICAL CONTACTS LIMITED | Q20: ELECTRICAL CONTACTS LIMITED
A21: =IF(OR(Q21<>"",R21<>""),"Y","N") -> Y | B21: WILFREDA EDWARD-DOLCY | C21: 767 | D21: ELECTRO MECHANICAL SRV LTD | E21: Y | F21: ELECTRO MECHANICAL SRV. LTD. | G21: NL | H21: MOUNT PEARL | I21: 92 GLENCOE AVE DONOVANS INDUSTRIAL PARK | J21: A1N 4S9 | K21: ACTIVE | L21: E423 | M21: 767 | N21: ELECTRO MECHANICAL SRV LTD | O21: 767E423 | P21: ELECTRO MECHANICAL SRV LTD | Q21: ELECTRO MECHANICAL SERVICES
A22: =IF(OR(Q22<>"",R22<>""),"Y","N") -> Y | B22: WILFREDA EDWARD-DOLCY | C22: 2532759 | D22: ELECTRO SONIC | E22: N | F22: Electro Sonic | G22: BC | H22: BURNABY | I22: 5489 BYRNE 173 | J22: V5J3J1 | K22: ACTIVE | L22: E423 | M22: 2532759 | N22: ELECTRO SONIC | O22: 2532759E423 | P22: ELECTRO SONIC | Q22: ELECTRO SONIC GROUP, INC.
A23: =IF(OR(Q23<>"",R23<>""),"Y","N") -> Y | B23: WILFREDA EDWARD-DOLCY | C23: 12308 | D23: ELECTRO SONIC INC | E23: N | F23: ELECTRO SONIC INC. | G23: ON | H23: WILLOWDALE | I23: 1100 GORDON BAKER RD. | J23: M2H 3B3 | K23: ACTIVE | L23: E423 | M23: 2532759 | N23: ELECTRO SONIC | O23: 2532759E423 | P23: ELECTRO SONIC | Q23: ELECTRO SONIC GROUP, INC.
A24: =IF(OR(Q24<>"",R24<>""),"Y","N") -> Y | B24: WILFREDA EDWARD-DOLCY | C24: 13828 | D24: ELECTRO WIND SUPPLY INC | E24: N | F24: ELECTRO-WIND SUPPLY INC. | G24: ON | H24: GUELPH | I24: 2 TAGGART CRT P.O. BOX 713 | J24: N1H 6L3 | K24: ACTIVE | L24: E423 | M24: 13828 | N24: ELECTRO WIND SUPPLY INC | O24: 13828E423 | P24: ELECTRO WIND SUPPLY INC | Q24: ELECTRO-WIND SUPPLY INC.
A25: =IF(OR(Q25<>"",R25<>""),"Y","N") -> Y | B25: WILFREDA EDWARD-DOLCY | C25: 12310 | D25: ELECTRONIC CRAFTSMEN LTD | E25: N | F25: ELECTRONIC CRAFTSMEN LTD. | G25: ON | H25: WATERLOO | I25: 73 SCHAEFER | J25: N2L4C4 | K25: ACTIVE | L25: E423 | M25: 12310 | N25: ELECTRONIC CRAFTSMEN LTD | O25: 12310E423 | P25: ELECTRONIC CRAFTSMEN LTD | Q25: E CRAFTSMEN CORPORATION
A26: =IF(OR(Q26<>"",R26<>""),"Y","N") -> Y | B26: WILFREDA EDWARD-DOLCY | C26: 6733067 | D26: ELECTRONIC RECYCLING ASSOCIATION | E26: N | F26: Electronic Recycling Association | G26: AB | H26: CALGARY | I26: 1301 34 | J26: T2G1V8 | K26: ACTIVE | L26: E423 | M26: 6733067 | N26: ELECTRONIC RECYCLING ASSOCIATION | O26: 6733067E423 | P26: ELECTRONIC RECYCLING ASSOCIATION | Q26: The Electronic Recycling Association of Alberta
A27: =IF(OR(Q27<>"",R27<>""),"Y","N") -> Y | B27: WILFREDA EDWARD-DOLCY | C27: 4112704 | D27: ELECTROVAYA INC | E27: N | F27: Electrovaya Inc. | G27: ON | H27: MISSISSAUGA | I27: 2645 ROYAL WINDSOR | J27: L5J1K9 | K27: ACTIVE | L27: E423 | M27: 4112704 | N27: ELECTROVAYA INC | O27: 4112704E423 | P27: ELECTROVAYA INC | Q27: ELECTROVAYA INC.
A28: =IF(OR(Q28<>"",R28<>""),"Y","N") -> Y | B28: WILFREDA EDWARD-DOLCY | C28: 3732606 | D28: ELEMENT | E28: N | F28: Element | G28: ON | H28: CAMBRIDGE | I28: 15 HIGH RIDGE | J28: N1R7L3 | K28: ACTIVE | L28: E455 | M28: 3732606 | N28: ELEMENT | O28: 3732606E455 | P28: ELEMENT | Q28: ELEMENT MATERIALS TECHNOLOGY CANADA INC.
A29: =IF(OR(Q29<>"",R29<>""),"Y","N") -> Y | B29: WILFREDA EDWARD-DOLCY | C29: 2773357 | D29: ELEY AIR SERVICE LTD | E29: N | F29: Eley Air Service Ltd | G29: SK | H29: COLONSAY | I29: 411 PO | J29: S0K0Z0 | K29: ACTIVE | L29: E462 | M29: 2773357 | N29: ELEY AIR SERVICE LTD | O29: 2773357E462 | P29: ELEY AIR SERVICE LTD | Q29: ELEY AIR SERVICE LTD.
A30: =IF(OR(Q30<>"",R30<>""),"Y","N") -> Y | B30: WILFREDA EDWARD-DOLCY | C30: 13783 | D30: ELGIN FIRE EXTINGUISHERS | E30: N | F30: ELGIN FIRE EXTINGUISHERS | G30: ON | H30: ST THOMAS | I30: 45123 ELM | J30: N5P3S6 | K30: ACTIVE | L30: E425 | M30: 13783 | N30: ELGIN FIRE EXTINGUISHERS | O30: 13783E425 | P30: ELGIN FIRE EXTINGUISHERS | Q30: ELGIN FIRE EXTINGUISHERS | S30: not found in DB
A31: =IF(OR(Q31<>"",R31<>""),"Y","N") -> Y | B31: WILFREDA EDWARD-DOLCY | C31: 13807 | D31: ELGIN MOTOR FREIGHT INC | E31: N | F31: ELGIN MOTOR FREIGHT INC. | G31: ON | H31: LONDON | I31: 1497 WILTON GROVE ROAD | J31: N6N 1M3 | K31: ACTIVE | L31: E425 | M31: 13807 | N31: ELGIN MOTOR FREIGHT INC | O31: 13807E425 | P31: ELGIN MOTOR FREIGHT INC | Q31: ELGIN MOTOR FREIGHT INC.
A32: =IF(OR(Q32<>"",R32<>""),"Y","N") -> Y | B32: WILFREDA EDWARD-DOLCY | C32: 12332 | D32: ELI LILLY CANADA INC | E32: Y | F32: ELI LILLY CANADA INC. | G32: ON | H32: SCARBOROUGH | I32: 3650 DANFORTH AVE. | J32: M1N 2E8 | K32: ACTIVE | L32: E444 | M32: 12332 | N32: ELI LILLY CANADA INC | O32: 12332E444 | P32: ELI LILLY CANADA INC | Q32: ELI LILLY CANADA INC
A33: =IF(OR(Q33<>"",R33<>""),"Y","N") -> Y | B33: WILFREDA EDWARD-DOLCY | C33: 1773107 | D33: ELIAS WOODWORK | E33: N | F33: Elias Woodwork | G33: MB | H33: WINKLER | I33: 1659 PO | J33: R6W4B5 | K33: ACTIVE | L33: E423 | M33: 1773107 | N33: ELIAS WOODWORK | O33: 1773107E423 | P33: ELIAS WOODWORK | Q33: ELIAS WOODWORKING AND MANUFACTURING LTD.
A34: =IF(OR(Q34<>"",R34<>""),"Y","N") -> Y | B34: WILFREDA EDWARD-DOLCY | C34: 15796 | D34: ELIRPA COSTRUCTION AND MATERIALS LIMITED | E34: N | F34: ELIRPA COSTRUCTION & MATERIALS LIMITED | G34: ON | H34: PICKERING | I34: P.O. BOX 187 2890 BROCK ROAD | J34: L1V 2R4 | K34: ACTIVE | L34: E461 | M34: 15796 | N34: ELIRPA COSTRUCTION AND MATERIALS LIMITED | O34: 15796E461 | P34: ELIRPA COSTRUCTION AND MATERIALS LIMITED | Q34: ELIRPA CONSTRUCTION & MATERIALS LIMITED
A35: =IF(OR(Q35<>"",R35<>""),"Y","N") -> Y | B35: WILFREDA EDWARD-DOLCY | C35: 9970 | D35: ELITE AUTOBODY | E35: Y | F35: ELITE AUTOBODY | G35: SK | H35: REGINA | I35: 240 HODSMAN ROAD | J35: S4N 5X4 | K35: ACTIVE | L35: E433 | M35: 9970 | N35: ELITE AUTOBODY | O35: 9970E433 | P35: ELITE AUTOBODY | Q35: ELITE AUTO BODY LTD.
A36: =IF(OR(Q36<>"",R36<>""),"Y","N") -> Y | B36: WILFREDA EDWARD-DOLCY | C36: 20966 | D36: ELITE FIRE PROTECTION LTD | E36: N | F36: ELITE FIRE PROTECTION LTD. | G36: BC | H36: ABBOTSFORD | I36: UNIT 1 - 33605 MCCLURE ROAD | J36: V2S 7W2 | K36: ACTIVE | L36: E431 | M36: 20966 | N36: ELITE FIRE PROTECTION LTD | O36: 20966E431 | P36: ELITE FIRE PROTECTION LTD | Q36: ELITE FIRE PROTECTION LTD.
A37: =IF(OR(Q37<>"",R37<>""),"Y","N") -> Y | B37: WILFREDA EDWARD-DOLCY | C37: 3254 | D37: ELITE FLEET | E37: N | F37: ELITE FLEET | G37: NB | H37: MONCTON | I37: 106 CALEDONIA ROD | J37: E1H 3C6 | K37: ACTIVE | L37: E431 | M37: 3254 | N37: ELITE FLEET | O37: 3254E431 | P37: ELITE FLEET | Q37: EASSONS TRANSPORT LIMITED
A38: =IF(OR(Q38<>"",R38<>""),"Y","N") -> Y | B38: WILFREDA EDWARD-DOLCY | C38: 2454933 | D38: ELITEMED INC | E38: N | F38: EliteMed Inc | G38: ON | H38: MISSISSAUGA | I38: 3190 RIDGEWAY 20 | J38: L5L5S8 | K38: ACTIVE | L38: E435 | M38: 2454933 | N38: ELITEMED INC | O38: 2454933E435 | P38: ELITEMED INC | Q38: ELITEMED INC.
A39: =IF(OR(Q39<>"",R39<>""),"Y","N") -> Y | B39: WILFREDA EDWARD-DOLCY | C39: 22365 | D39: ELK VALLEY COAL GREEN HILLS OPERATION | E39: N | F39: ELK VALLEY COAL [GREEN HILLS OPERATION] | G39: BC | H39: ELKFORD | I39: 6 KM NORTH OF ELKFORD | J39: VOB 1H0 | K39: ACTIVE | L39: E421 | M39: 22365 | N39: ELK VALLEY COAL GREEN HILLS OPERATION | O39: 22365E421 | P39: ELK VALLEY COAL GREEN HILLS OPERATION | Q39: ELK VALLEY COAL [GREEN HILLS OPERATION / POSCO Canada Limited]
A40: =IF(OR(Q40<>"",R40<>""),"Y","N") -> Y | B40: WILFREDA EDWARD-DOLCY | C40: 6236 | D40: ELKEM METAL CANADA INC | E40: N | F40: ELKEM MÉTAL CANADA INC. | G40: QC | H40: CHICOUTIMI | I40: 2020 DE LA RÉSERVE | J40: G7J0E1 | K40: ACTIVE | L40: E425 | M40: 6236 | N40: ELKEM METAL CANADA INC | O40: 6236E425 | P40: ELKEM METAL CANADA INC | Q40: ELKEM MÉTAL CANADA INC.
...

Sheet SUMMARY
A1: Start Date | B1: 44167
A2: End Date
A4: ALL SITES
A5: NAMES | B5: ASSIGNED | C5: COMPLETE | D5: %
A6: QIONG LI | B6: =COUNTIF(MATCHRESULTS!$B$2:$B$13000,SUMMARY!A6) -> 2477 | C6: =COUNTIFS(MATCHRESULTS!$B$2:$B$13000,SUMMARY!A6,MATCHRESULTS!$A$2:$A$13000,"Y") -> 2414 | D6: =C6/B6 -> 0.97456601
A7: DESMOND YELLAND | B7: =COUNTIF(MATCHRESULTS!$B$2:$B$13000,SUMMARY!A7) -> 2477 | C7: =COUNTIFS(MATCHRESULTS!$B$2:$B$13000,SUMMARY!A7,MATCHRESULTS!$A$2:$A$13000,"Y") -> 603 | D7: =C7/B7 -> 0.24343964
A8: WILFREDA EDWARD-DOLCY | B8: =COUNTIF(MATCHRESULTS!$B$2:$B$13000,SUMMARY!A8) -> 2477 | C8: =COUNTIFS(MATCHRESULTS!$B$2:$B$13000,SUMMARY!A8,MATCHRESULTS!$A$2:$A$13000,"Y") -> 1179 | D8: =C8/B8 -> 0.47597901
A9: MITCHELL JACKSON | B9: =COUNTIF(MATCHRESULTS!$B$2:$B$13000,SUMMARY!A9) -> 2477 | C9: =COUNTIFS(MATCHRESULTS!$B$2:$B$13000,SUMMARY!A9,MATCHRESULTS!$A$2:$A$13000,"Y") -> 195 | D9: =C9/B9 -> 0.078724263
A10: TATIANA KOLECHKINA | B10: =COUNTIF(MATCHRESULTS!$B$2:$B$13000,SUMMARY!A10) -> 2477 | C10: =COUNTIFS(MATCHRESULTS!$B$2:$B$13000,SUMMARY!A10,MATCHRESULTS!$A$2:$A$13000,"Y") -> 2477 | D10: =C10/B10 -> 1
A11: TOTAL | B11: =SUM(B6:B10) -> 12385 | C11: =SUM(C6:C10) -> 6868 | D11: =C11/B11 -> 0.55454178
A13: Planned2021="Y"
A14: NAMES | B14: ASSIGNED | C14: COMPLETE | D14: %
A15: QIONG LI | B15: =COUNTIFS(MATCHRESULTS!$B$2:$B$13000,SUMMARY!A15,MATCHRESULTS!$E$2:$E$13000,"Y") -> 511 | C15: =COUNTIFS(MATCHRESULTS!$B$2:$B$13000,SUMMARY!A15,MATCHRESULTS!$A$2:$A$13000,"Y",MATCHRESULTS!$E$2:$E$13000,"Y") -> 503 | D15: =C15/B15 -> 0.98434442
A16: DESMOND YELLAND | B16: =COUNTIFS(MATCHRESULTS!$B$2:$B$13000,SUMMARY!A16,MATCHRESULTS!$E$2:$E$13000,"Y") -> 573 | C16: =COUNTIFS(MATCHRESULTS!$B$2:$B$13000,SUMMARY!A16,MATCHRESULTS!$A$2:$A$13000,"Y",MATCHRESULTS!$E$2:$E$13000,"Y") -> 435 | D16: =C16/B16 -> 0.7591623
A17: WILFREDA EDWARD-DOLCY | B17: =COUNTIFS(MATCHRESULTS!$B$2:$B$13000,SUMMARY!A17,MATCHRESULTS!$E$2:$E$13000,"Y") -> 536 | C17: =COUNTIFS(MATCHRESULTS!$B$2:$B$13000,SUMMARY!A17,MATCHRESULTS!$A$2:$A$13000,"Y",MATCHRESULTS!$E$2:$E$13000,"Y") -> 536 | D17: =C17/B17 -> 1
A18: MITCHELL JACKSON | B18: =COUNTIFS(MATCHRESULTS!$B$2:$B$13000,SUMMARY!A18,MATCHRESULTS!$E$2:$E$13000,"Y") -> 546 | C18: =COUNTIFS(MATCHRESULTS!$B$2:$B$13000,SUMMARY!A18,MATCHRESULTS!$A$2:$A$13000,"Y",MATCHRESULTS!$E$2:$E$13000,"Y") -> 128 | D18: =C18/B18 -> 0.23443223
A19: TATIANA KOLECHKINA | B19: =COUNTIFS(MATCHRESULTS!$B$2:$B$13000,SUMMARY!A19,MATCHRESULTS!$E$2:$E$13000,"Y") -> 810 | C19: =COUNTIFS(MATCHRESULTS!$B$2:$B$13000,SUMMARY!A19,MATCHRESULTS!$A$2:$A$13000,"Y",MATCHRESULTS!$E$2:$E$13000,"Y") -> 810 | D19: =C19/B19 -> 1
A20: TOTAL | B20: =SUM(B15:B19) -> 2976 | C20: =SUM(C15:C19) -> 2412 | D20: =C20/B20 -> 0.81048387

Sheet RULES
A2: For consistency, if you have made a decision which could be leveraged for a similar situation later, please record the steps here
A4: 1) ACME SUPPLIES is owned by BUNZL CANADA INC., should have BUNZL's ID
A5: 2) "<name> Co-operative Association Limited" is owned by "Federated Co-operatives Limited"
